Workbook

Sheet Léame
A1: NARA · Datos de prueba · BORRADOR para revisar
A2: Generado desde nara_datos_prueba.json (versión 2.0, reglas v2) · fecha de referencia 2026-10-08.
A3: Borrador: no trae contraseñas. Se generan con «node generar_excel.js --final».
A5: Qué contiene
A6: • 36 cuentas: 1 administrador, 5 experto de campo, 5 clínico, 5 observador, 20 paciente.
A7: • 5 territorios: Bucaramanga, Floridablanca, Bogotá, Cali, Barranquilla. Cada uno con 1 experto, 1 clínico y 1 observador.
A8: • 20 pacientes de la base 2022: 15 evaluados (uno por perfil P01–P15) y 5 «Sin evaluación» (uno por territorio).
A9: • 13 activos y 1 cambio(s) de ruta para la líder clínica.
A11: Hojas
A12: • Matriz y Reglas: los 15 perfiles con su ruta v2 y las reglas de clasificación aprobadas el 8 oct 2026.
A13: • Territorios, Usuarios y Asignaciones: quién trabaja dónde y con quién.
A14: • Pacientes: datos de la base 2022 y respuestas de la entrevista. Si se cambia una respuesta, el perfil se recalcula y los checks lo marcan.
... A36: • No guardar modulesEnabled en los pacientes: así la app muestra su ruta.

Sheet Matriz
A1: Perfil | B1: Riesgo (PHQ-9) | C1: Puntaje PHQ-9 | D1: Capacidad digital | E1: Puntaje digital | F1: Canal principal | G1: Nº servicios | H1: Ruta v2 (servicio y frecuencia) | I1: Meses | J1: Cursos y cuentos | K1: Paciente de prueba | L1: Estado
A2: P01 | B2: Mínimo | C2: 0–4 | D2: Baja | E2: 0–4 | F2: Teléfono, visita y material impreso | G2: 5 | H2: Llamada de seguimiento (Mensual) · Técnicas guiadas (Material impreso) · Revisita del experto (Mensual) · Grupo de apoyo en la vereda (Mensual) · Cursos y cuentos (Curso con el experto) | I2: 3 | J2: Curso con el experto · Cuadernillo impreso · audio en la visita | K2: Darly Yasmin Solano (BUC-SM436) | L2: Inactivo
A3: P02 | B3: Mínimo | C3: 0–4 | D3: Media | E3: 5–8 | F3: WhatsApp (audio primero) | G3: 5 | H3: Check-ins por WhatsApp (1 vez por semana) · Videos psicoeducativos (Serie completa) · Técnicas guiadas (En audio) · Grupo de apoyo en la vereda (Mensual) · Cursos y cuentos (Curso guiado por TEO) | I3: 3 | J3: Curso guiado por TEO · WhatsApp · portada, audio y pregunta | K3: Mariluz (BAR-SM351) | L3: Activo
A4: P03 | B4: Mínimo | C4: 0–4 | D4: Alta | E4: 9–11 | F4: App + WhatsApp | G4: 6 | H4: Estado de ánimo (Diario) · Acompañante con IA (TEO) (Acceso libre) · Check-ins por WhatsApp (1 vez por semana) · Videos psicoeducativos (Serie completa) · Técnicas guiadas (En audio) · Cursos y cuentos (Curso guiado por TEO) | I4: 3 | J4: Curso guiado por TEO · App · leer y escuchar | K4: Yessenia Coime (CAL-SM204) | L4: Por aprobar
A5: P04 | B5: Leve | C5: 5–9 | D5: Baja | E5: 0–4 | F5: Teléfono, visita y material impreso | G5: 5 | H5: Llamada de seguimiento (Mensual) · Técnicas guiadas (Material impreso) · Revisita del experto (Cada 2 semanas) · Grupo de apoyo en la vereda (Mensual) · Cursos y cuentos (Curso con el experto) | I5: 3 | J5: Curso con el experto · Cuadernillo impreso · audio en la visita | K5: Sandra Milena García Pinto (FLO-SM435) | L5: Activo
A6: P05 | B6: Leve | C6: 5–9 | D6: Media | E6: 5–8 | F6: WhatsApp (audio primero) | G6: 6 | H6: Check-ins por WhatsApp (1 vez por semana) · Videos psicoeducativos (Serie completa) · Técnicas guiadas (En audio) · Revisita del experto (Mensual) · Grupo de apoyo en la vereda (Mensual) · Cursos y cuentos (Curso guiado por TEO) | I6: 3 | J6: Curso guiado por TEO · WhatsApp · portada, audio y pregunta | K6: Cristian Páez Pérez (BUC-SM496) | L6: Activo
A7: P06 | B7: Leve | C7: 5–9 | D7: Alta | E7: 9–11 | F7: App + WhatsApp | G7: 7 | H7: Estado de ánimo (Diario) · Acompañante con IA (TEO) (Acceso libre) · Check-ins por WhatsApp (1 vez por semana) · Videos psicoeducativos (Serie completa) · Técnicas guiadas (En audio) · Revisita del experto (Mensual) · Cursos y cuentos (Curso guiado por TEO) | I7: 3 | J7: Curso guiado por TEO · App · leer y escuchar | K7: Andreina (BAR-SM300) | L7: Por aprobar
A8: P07 | B8: Moderado | C8: 10–14 | D8: Baja | E8: 0–4 | F8: Teléfono, visita y material impreso | G8: 8 | H8: Psicólogo clínico (Mensual) · Llamada de seguimiento (Semanal) · Manilla de monitoreo (6 meses) · Técnicas guiadas (Material impreso) · Revisita del experto (Cada 2 semanas) · Problem Management Plus (PM+) (5 sesiones semanales) · Grupo de apoyo en la vereda (Quincenal) · Cursos y cuentos (Curso con el experto) | I8: 6 | J8: Curso con el experto · Cuadernillo impreso · audio en la visita | K8: Ana Rojas (BOG-SM347) | L8: Activo
A9: P08 | B9: Moderado | C9: 10–14 | D9: Media | E9: 5–8 | F9: WhatsApp (audio primero) | G9: 8 | H9: Psicólogo clínico (Mensual) · Check-ins por WhatsApp (3 veces por semana) · Manilla de monitoreo (6 meses) · Videos psicoeducativos (Serie completa) · Técnicas guiadas (En audio) · Problem Management Plus (PM+) (5 sesiones semanales) · Grupo de apoyo en la vereda (Quincenal) · Cursos y cuentos (Curso con el experto) | I9: 6 | J9: Curso con el experto · WhatsApp · portada, audio y pregunta | K9: Vanessa Castellanos (FLO-SM434) | L9: Por aprobar
A10: P09 | B10: Moderado | C10: 10–14 | D10: Alta | E10: 9–11 | F10: App + WhatsApp | G10: 9 | H10: Estado de ánimo (Diario) · Psicólogo clínico (Mensual) · Acompañante con IA (TEO) (Entre sesiones) · Check-ins por WhatsApp (3 veces por semana) · Manilla de monitoreo (6 meses) · Videos psicoeducativos (Serie completa) · Técnicas guiadas (En audio) · Problem Management Plus (PM+) (5 sesiones semanales) · Cursos y cuentos (Curso con el experto) | I10: 6 | J10: Curso con el experto · App · leer y escuchar | K10: Silvia Margarita Martínez Franco (BUC-SM135) | L10: Por aprobar
A11: P10 | B11: Moderado-severo | C11: 15–19 | D11: Baja | E11: 0–4 | F11: Teléfono, visita y material impreso | G11: 8 | H11: Psicólogo clínico (Quincenal) · Llamada de seguimiento (Semanal) · Manilla de monitoreo (12 meses) · Técnicas guiadas (Material impreso) · Revisita del experto (Cada 2 semanas) · Problem Management Plus (PM+) (5 sesiones semanales) · Grupo de apoyo en la vereda (Quincenal) · Cursos y cuentos (Asignado por la psicóloga) | I11: 12 | J11: Asignado por la psicóloga · Cuadernillo impreso · audio en la visita | K11: Lorena Lasso (CAL-SM352) | L11: Aprobado
A12: P11 | B12: Moderado-severo | C12: 15–19 | D12: Media | E12: 5–8 | F12: WhatsApp (audio primero) | G12: 9 | H12: Psicólogo clínico (Quincenal) · Check-ins por WhatsApp (3 veces por semana) · Manilla de monitoreo (12 meses) · Videos psicoeducativos (Serie completa) · Técnicas guiadas (En audio) · Revisita del experto (Cada 2 semanas) · Problem Management Plus (PM+) (5 sesiones semanales) · Grupo de apoyo en la vereda (Quincenal) · Cursos y cuentos (Asignado por la psicóloga) | I12: 12 | J12: Asignado por la psicóloga · WhatsApp · portada, audio y pregunta | K12: Julieth (BOG-SM321) | L12: Rechazado
A13: P12 | B13: Moderado-severo | C13: 15–19 | D13: Alta | E13: 9–11 | F13: App + WhatsApp | G13: 10 | H13: Estado de ánimo (Diario) · Psicólogo clínico (Quincenal) · Acompañante con IA (TEO) (Entre sesiones) · Check-ins por WhatsApp (3 veces por semana) · Manilla de monitoreo (12 meses) · Videos psicoeducativos (Serie completa) · Técnicas guiadas (En audio) · Revisita del experto (Cada 2 semanas) · Problem Management Plus (PM+) (5 sesiones semanales) · Cursos y cuentos (Asignado por la psicóloga) | I13: 12 | J13: Asignado por la psicóloga · App · leer y escuchar | K13: Paula Pimienta (FLO-SM365) | L13: Activo
... A16: P15 | B16: Severo | C16: 20–27 | D16: Alta | E16: 9–11 | F16: App + WhatsApp | G16: 8 | H16: Estado de ánimo (Diario) · Psicólogo clínico (Semanal) · Check-ins por WhatsApp (3 veces por semana) · Manilla de monitoreo (12 meses) · Videos psicoeducativos (Serie completa) · Técnicas guiadas (En audio) · Revisita del experto (Cada 2 semanas) · Cursos y cuentos (Asignado por la psicóloga) | I16: 12 | J16: Asignado por la psicóloga · App · leer y escuchar | K16: Isabel (BOG-SM237) | L16: Por aprobar
A19: Cuadro de perfiles: riesgo × capacidad digital
B20: Riesgo \ Digital | F20: Baja (0–4 o sin teléfono) | H20: Media (5–8) | J20: Alta (9–11)
B21: Mínimo (0–4) | F21: P01 · Darly Yasmin Solano (BUC) | H21: P02 · Mariluz (BAR) | J21: P03 · Yessenia Coime (CAL)
B22: Leve (5–9) | F22: P04 · Sandra Milena García Pinto (FLO) | H22: P05 · Cristian Páez Pérez (BUC) | J22: P06 · Andreina (BAR)
B23: Moderado (10–14) | F23: P07 · Ana Rojas (BOG) | H23: P08 · Vanessa Castellanos (FLO) | J23: P09 · Silvia Margarita Martínez Franco (BUC)
B24: Moderado-severo (15–19) | F24: P10 · Lorena Lasso (CAL) | H24: P11 · Julieth (BOG) | J24: P12 · Paula Pimienta (FLO)
B25: Severo (20–27) | F25: P13 · Neil (BAR) | H25: P14 · Andrés (CAL) | J25: P15 · Isabel (BOG)

Sheet Reglas
A1: Reglas de clasificación v2 (aprobadas el 8 oct 2026)
A3: Clasificación
A4: • Riesgo PHQ-9 (9 preguntas de 0 a 3, total 0–27): Mínimo 0–4 · Leve 5–9 · Moderado 10–14 · Moderado-severo 15–19 · Severo 20–27.
A5: • Capacidad digital (6 preguntas, total 0–11): Baja 0–4 · Media 5–8 · Alta 9–11.
A6: • Sin teléfono (pregunta 1 = «Ninguno») ⇒ Baja, sin importar el puntaje.
A7: • «Uso diario» (pregunta 3) no puede ser mayor que «Teléfono» (pregunta 1): no deja calcular el resultado.
A8: • Perfil = riesgo × 3 + digital + 1 → P01 (Mínimo × Baja) a P15 (Severo × Alta).
A9: • Crisis: pregunta 9 mayor que 0 ⇒ alerta inmediata al clínico de turno del territorio.
A11: Seguimiento (decidido el 8 oct 2026)
A12: • El contacto se mide por el canal de la capacidad digital: Alta = ingreso a la app · Media = respuesta por WhatsApp · Baja = llamada o revisita.
A13: • 14 días sin contacto ⇒ alerta «Sin contacto» para que el experto la busque; la persona sigue Activa.
A14: • Más de 28 días sin contacto ⇒ estado Inactivo. Un contacto nuevo la devuelve sola a Activo.
... A27: • ¿Se acepta Crisis antes de la aprobación cuando la pregunta 9 sale positiva en la visita? (caso de Neil, BAR)

Sheet Territorios
A1: Código | B1: Territorio | C1: Departamento | D1: Nivel | E1: Meta de captación | F1: Rural mínima % | G1: 60+ mínima % | H1: Contenido local | I1: Lugares | J1: Experto de campo | K1: Clínico | L1: Observador | M1: Experto (ID cuenta) | N1: Clínico (ID cuenta) | O1: Observador (ID cuenta)
A2: BUC | B2: Bucaramanga | C2: Santander | D2: Municipio completo | E2: 50 | F2: 0 | G2: 0 | H2: PHQ-9 + capacidad digital (base) | I2: Bucaramanga, Santander | J2: Laura Milena Rueda Pinzón | K2: Dra. Adriana Marcela Gómez Duarte | L2: Mónica Liliana Parra Ortiz | M2: u-exp-bucaramanga | N2: u-cli-bucaramanga | O2: u-obs-bucaramanga
A3: FLO | B3: Floridablanca | C3: Santander | D3: Municipio completo | E3: 50 | F3: 0 | G3: 0 | H3: PHQ-9 + capacidad digital (base) | I3: Floridablanca, Santander | J3: Jhon Fredy Ardila Serrano | K3: Dr. Felipe Augusto Quintero Mantilla | L3: Hernán Darío Suárez León | M3: u-exp-floridablanca | N3: u-cli-floridablanca | O3: u-obs-floridablanca
A4: BOG | B4: Bogotá | C4: Bogotá D.C. | D4: Municipio completo | E4: 50 | F4: 0 | G4: 0 | H4: PHQ-9 + capacidad digital (base) | I4: Bogotá, Bogotá D.C. | J4: Natalia Andrea Cárdenas Moreno | K4: Dra. Lucía Marín | L4: Carolina Ospina Ríos | M4: u-exp-bogota | N4: umuvzhvkb | O4: u-obs-bogota
A5: CAL | B5: Cali | C5: Valle del Cauca | D5: Municipio completo | E5: 50 | F5: 0 | G5: 0 | H5: PHQ-9 + capacidad digital (base) | I5: Cali, Valle del Cauca | J5: Carlos Andrés Mosquera Valencia | K5: Dra. Paola Andrea Caicedo Arboleda | L5: Julián Esteban Arango Muñoz | M5: u-exp-cali | N5: u-cli-cali | O5: u-obs-cali
A6: BAR | B6: Barranquilla | C6: Atlántico | D6: Municipio completo | E6: 50 | F6: 0 | G6: 0 | H6: PHQ-9 + capacidad digital (base) | I6: Barranquilla, Atlántico | J6: Katherine Paola De la Hoz Charris | K6: Dr. Rafael Enrique Barrios Pertuz | L6: Mariana Isabel Vergara Palencia | M6: u-exp-barranquilla | N6: u-cli-barranquilla | O6: u-obs-barranquilla

Sheet Usuarios
A1: ID cuenta | B1: Rol | C1: Nombre | D1: Correo | E1: Teléfono | F1: Territorio | G1: Organización | H1: Líder clínica | I1: Estado de la cuenta | J1: Experto · ID en experts | K1: Experto · meta por día | L1: Experto · meta por semana | M1: Experto · tablet | N1: Experto · capacitación | O1: Observador · módulos | P1: Paciente · ID paciente | Q1: Paciente · perfil listo (profileReady) | R1: Origen de los datos | S1: Nota | T1: Contraseña inicial (temporal)
A2: admin | B2: Administrador | C2: Administrador NARA | D2: admin@nara.com | F2: Todos | G2: Programa NARA | I2: Activo | R2: Cuenta existente (reusar) | S2: Rotar la clave actual: AdminNara2026 está en el repositorio (hallazgo S-4). | T2: (versión final)
A3: u-exp-bucaramanga | B3: Experto de campo | C3: Laura Milena Rueda Pinzón | D3: laura.rueda@nara.com | E3: 300 000 0101 | F3: Bucaramanga | G3: Programa NARA | I3: Activo | J3: exp-bucaramanga | K3: 9 | L3: 45 | M3: TB-001 | N3: Completa | R3: Ficticio | T3: (versión final)
A4: u-exp-floridablanca | B4: Experto de campo | C4: Jhon Fredy Ardila Serrano | D4: jhon.ardila@nara.com | E4: 300 000 0102 | F4: Floridablanca | G4: Programa NARA | I4: Activo | J4: exp-floridablanca | K4: 9 | L4: 45 | M4: TB-002 | N4: Completa | R4: Ficticio | T4: (versión final)
A5: u-exp-bogota | B5: Experto de campo | C5: Natalia Andrea Cárdenas Moreno | D5: natalia.cardenas@nara.com | E5: 300 000 0103 | F5: Bogotá | G5: Programa NARA | I5: Activo | J5: exp-bogota | K5: 9 | L5: 45 | M5: TB-003 | N5: Completa | R5: Ficticio | T5: (versión final)
A6: u-exp-cali | B6: Experto de campo | C6: Carlos Andrés Mosquera Valencia | D6: carlos.mosquera@nara.com | E6: 300 000 0104 | F6: Cali | G6: Programa NARA | I6: Activo | J6: exp-cali | K6: 9 | L6: 45 | M6: TB-004 | N6: Completa | R6: Ficticio | T6: (versión final)
A7: u-exp-barranquilla | B7: Experto de campo | C7: Katherine Paola De la Hoz Charris | D7: katherine.delahoz@nara.com | E7: 300 000 0105 | F7: Barranquilla | G7: Programa NARA | I7: Activo | J7: exp-barranquilla | K7: 9 | L7: 45 | M7: TB-005 | N7: Completa | R7: Ficticio | T7: (versión final)
A8: u-cli-bucaramanga | B8: Clínico | C8: Dra. Adriana Marcela Gómez Duarte | D8: adriana.gomez@nara.com | E8: 300 000 0201 | F8: Bucaramanga | G8: Programa NARA | H8: No | I8: Activo | R8: Ficticio | T8: (versión final)
A9: u-cli-floridablanca | B9: Clínico | C9: Dr. Felipe Augusto Quintero Mantilla | D9: felipe.quintero@nara.com | E9: 300 000 0202 | F9: Floridablanca | G9: Programa NARA | H9: No | I9: Activo | R9: Ficticio | T9: (versión final)
A10: umuvzhvkb | B10: Clínico | C10: Dra. Lucía Marín | D10: lucia.marin@nara.com | E10: 300 000 0203 | F10: Bogotá | G10: Programa NARA | H10: Sí | I10: Activo | R10: Cuenta existente (reusar); cambia de Quindío a Bogotá | T10: (versión final)
A11: u-cli-cali | B11: Clínico | C11: Dra. Paola Andrea Caicedo Arboleda | D11: paola.caicedo@nara.com | E11: 300 000 0204 | F11: Cali | G11: Programa NARA | H11: No | I11: Activo | R11: Ficticio | T11: (versión final)
A12: u-cli-barranquilla | B12: Clínico | C12: Dr. Rafael Enrique Barrios Pertuz | D12: rafael.barrios@nara.com | E12: 300 000 0205 | F12: Barranquilla | G12: Programa NARA | H12: No | I12: Activo | R12: Ficticio | T12: (versión final)
A13: u-obs-bucaramanga | B13: Observador | C13: Mónica Liliana Parra Ortiz | D13: monica.parra@nara.com | E13: 300 000 0301 | F13: Bucaramanga | G13: Fundación NARA | I13: Activo | O13: Avance del territorio (agregado) · Resultados (agregado) · TEO | R13: Ficticio | T13: (versión final)
A14: u-obs-floridablanca | B14: Observador | C14: Hernán Darío Suárez León | D14: hernan.suarez@nara.com | E14: 300 000 0302 | F14: Floridablanca | G14: Fundación NARA | I14: Activo | O14: Avance del territorio (agregado) · Resultados (agregado) · TEO | R14: Ficticio | T14: (versión final)
A15: u-obs-bogota | B15: Observador | C15: Carolina Ospina Ríos | D15: carolina.ospina@nara.com | E15: 300 000 0303 | F15: Bogotá | G15: Centro de Investigación NARA | I15: Activo | O15: Avance del territorio (agregado) · Resultados (agregado) · TEO | R15: Ficticio | T15: (versión final)
A16: u-obs-cali | B16: Observador | C16: Julián Esteban Arango Muñoz | D16: julian.arango@nara.com | E16: 300 000 0304 | F16: Cali | G16: Centro de Investigación NARA | I16: Activo | O16: Avance del territorio (agregado) · Resultados (agregado) · TEO | R16: Ficticio | T16: (versión final)
A17: u-obs-barranquilla | B17: Observador | C17: Mariana Isabel Vergara Palencia | D17: mariana.vergara@nara.com | E17: 300 000 0305 | F17: Barranquilla | G17: Red de Salud Aliada NARA | I17: Activo | O17: Avance del territorio (agregado) · Resultados (agregado) · TEO | R17: Ficticio | T17: (versión final)
A18: u-pac-sm-436 | B18: Paciente | C18: Darly Yasmin Solano | D18: buc-sm436@pacientes.nara.local | E18: 300 000 1436 | F18: Bucaramanga | G18: Programa NARA | I18: Activo | P18: sm-436 | Q18: Sí | R18: Real (base 2022) · correo y teléfono ficticios | T18: (versión final)
A19: u-pac-sm-496 | B19: Paciente | C19: Cristian Páez Pérez | D19: buc-sm496@pacientes.nara.local | E19: 300 000 1496 | F19: Bucaramanga | G19: Programa NARA | I19: Activo | P19: sm-496 | Q19: Sí | R19: Real (base 2022) · correo y teléfono ficticios | T19: (versión final)
A20: u-pac-sm-135 | B20: Paciente | C20: Silvia Margarita Martínez Franco | D20: buc-sm135@pacientes.nara.local | E20: 300 000 1135 | F20: Bucaramanga | G20: Programa NARA | I20: Activo | P20: sm-135 | Q20: No | R20: Real (base 2022) · correo y teléfono ficticios | T20: (versión final)
A21: u-pac-sm-435 | B21: Paciente | C21: Sandra Milena García Pinto | D21: flo-sm435@pacientes.nara.local | E21: 300 000 1435 | F21: Floridablanca | G21: Programa NARA | I21: Activo | P21: sm-435 | Q21: Sí | R21: Real (base 2022) · correo y teléfono ficticios | T21: (versión final)
A22: u-pac-sm-434 | B22: Paciente | C22: Vanessa Castellanos | D22: flo-sm434@pacientes.nara.local | E22: 300 000 1434 | F22: Floridablanca | G22: Programa NARA | I22: Activo | P22: sm-434 | Q22: No | R22: Real (base 2022) · correo y teléfono ficticios | T22: (versión final)
A23: u-pac-sm-365 | B23: Paciente | C23: Paula Pimienta | D23: flo-sm365@pacientes.nara.local | E23: 300 000 1365 | F23: Floridablanca | G23: Programa NARA | I23: Activo | P23: sm-365 | Q23: Sí | R23: Real (base 2022) · correo y teléfono ficticios | T23: (versión final)
A24: u-pac-sm-347 | B24: Paciente | C24: Ana Rojas | D24: bog-sm347@pacientes.nara.local | E24: 300 000 1347 | F24: Bogotá | G24: Programa NARA | I24: Activo | P24: sm-347 | Q24: Sí | R24: Real (base 2022) · correo y teléfono ficticios | T24: (versión final)
A25: u-pac-sm-321 | B25: Paciente | C25: Julieth | D25: bog-sm321@pacientes.nara.local | E25: 300 000 1321 | F25: Bogotá | G25: Programa NARA | I25: Activo | P25: sm-321 | Q25: No | R25: Real (base 2022) · correo y teléfono ficticios | T25: (versión final)
A26: u-pac-sm-237 | B26: Paciente | C26: Isabel | D26: bog-sm237@pacientes.nara.local | E26: 300 000 1237 | F26: Bogotá | G26: Programa NARA | I26: Activo | P26: sm-237 | Q26: No | R26: Real (base 2022) · correo y teléfono ficticios | T26: (versión final)
A27: u-pac-sm-352 | B27: Paciente | C27: Lorena Lasso | D27: cal-sm352@pacientes.nara.local | E27: 300 000 1352 | F27: Cali | G27: Programa NARA | I27: Activo | P27: sm-352 | Q27: Sí | R27: Real (base 2022) · correo y teléfono ficticios | T27: (versión final)
A28: u-pac-sm-182 | B28: Paciente | C28: Andrés | D28: cal-sm182@pacientes.nara.local | E28: 300 000 1182 | F28: Cali | G28: Programa NARA | I28: Activo | P28: sm-182 | Q28: Sí | R28: Real (base 2022) · correo y teléfono ficticios | T28: (versión final)
A29: u-pac-sm-204 | B29: Paciente | C29: Yessenia Coime | D29: cal-sm204@pacientes.nara.local | E29: 300 000 1204 | F29: Cali | G29: Programa NARA | I29: Activo | P29: sm-204 | Q29: No | R29: Real (base 2022) · correo y teléfono ficticios | T29: (versión final)
... A37: u-pac-sm-187 | B37: Paciente | C37: Esmy | D37: bar-sm187@pacientes.nara.local | E37: 300 000 1187 | F37: Barranquilla | G37: Programa NARA | I37: Activo | P37: sm-187 | Q37: No | R37: Real (base 2022) · correo y teléfono ficticios | T37: (versión final)

Sheet Pacientes
A1: ID paciente | B1: Código | C1: ID original 2022 | D1: Nombre | E1: Origen del nombre | F1: Valor original en la base | G1: Edad | H1: Sexo | I1: Identidad de género | J1: Estado civil | K1: Estrato | L1: Municipio (base 2022) | M1: Fecha de registro 2022 | N1: Territorio | O1: Experto de campo | P1: Clínico | Q1: Experto (ID cuenta) | R1: Clínico (ID cuenta) | S1: Cuenta del paciente (ID) | T1: Correo (ficticio) | U1: Teléfono (ficticio) | V1: Estado | W1: PHQ 1 · Poco interés o placer en hacer las cosas | X1: PHQ 2 · Se ha sentido decaído/a, deprimido/a o sin esperanza | Y1: PHQ 3 · Dificultad para dormir o dormir demasiado | Z1: PHQ 4 · Se ha sentido cansado/a o con poca energía | AA1: PHQ 5 · Poco apetito o come en exceso | AB1: PHQ 6 · Se ha sentido mal consigo mismo/a, o una carga para su familia | AC1: PHQ 7 · Dificultad para concentrarse | AD1: PHQ 8 · Se mueve o habla muy lento, o está muy inquieto/a | AE1: PHQ 9 · Pensamientos de que estaría mejor muerto/a o de hacerse daño | AF1: PHQ-9 total | AG1: Riesgo | AH1: DIG 1 · Teléfono (0 Ninguno, 1 Compartido, 2 Smartphone propio) | AI1: DIG 2 · Conexión en casa (0 Sin señal, 1 Datos limitados, 2 Estable) | AJ1: DIG 3 · Uso diario (0 Solo llamadas, 1 WhatsApp y audios, 2 Apps y videollamadas) | AK1: DIG 4 · Lectura y escritura (0 Prefiere voz, 1 Básica, 2 Cómoda) | AL1: DIG 5 · ¿Hablaría con una app? (0 No, 1 Tal vez, 2 Sí) | AM1: DIG 6 · Alguien en casa le ayuda con el celular (0 No, 1 Sí) | AN1: Digital total | AO1: Capacidad digital | AP1: Nota de capacidad digital | AQ1: Contexto · daño en la vivienda (0 Ninguno, 1 Parcial, 2 Total) | AR1: Contexto · perdió a un familiar (0 No, 1 Sí) | AS1: Perfil (JSON) | AT1: Perfil calculado | AU1: Check · perfil = respuestas | AV1: Check · experto del territorio | AW1: Check · clínico del territorio | AX1: Check · edad ≥ 18 | AY1: Check · uso ≤ teléfono
A2: sm-436 | B2: BUC-SM436 | C2: 436 | D2: Darly Yasmin Solano | E2: Real · nombre y apellido | F2: Darly yasmin solano | G2: 27 | H2: Femenino | I2: Femenino | J2: Unión Libre | K2: 1 | L2: Bucaramanga | M2: 44735 | N2: BUC | O2: Laura Milena Rueda Pinzón | P2: Dra. Adriana Marcela Gómez Duarte | Q2: u-exp-bucaramanga | R2: u-cli-bucaramanga | S2: u-pac-sm-436 | T2: buc-sm436@pacientes.nara.local | U2: 300 000 1436 | V2: Inactivo | W2: 0 | X2: 1 | Y2: 1 | Z2: 1 | AA2: 0 | AB2: 0 | AC2: 0 | AD2: 0 | AE2: 0 | AF2: =IF(COUNT(W2:AE2)=0,"",SUM(W2:AE2)) -> 3 | AG2: =IF(AF2="","",LOOKUP(AF2,{0,5,10,15,20},{"Mínimo","Leve","Moderado","Moderado-severo","Severo"})) -> Mínimo | AH2: 1 | AI2: 0 | AJ2: 0 | AK2: 0 | AL2: 1 | AM2: 0 | AN2: =IF(COUNT(AH2:AM2)=0,"",SUM(AH2:AM2)) -> 2 | AO2: =IF(AN2="","",IF(AH2=0,"Baja",LOOKUP(AN2,{0,5,9},{"Baja","Media","Alta"}))) -> Baja | AP2: =IF(AN2="","",IF(AH2=0,"Sin teléfono: la capacidad digital queda en Baja.",IF(LOOKUP(AN2-AM2,{0,5,9},{"Baja","Media","Alta"})<>AO2,"El apoyo de un familiar sube el nivel de "&LOOKUP(AN2-AM2,{0,5,9},{"Baja","Media","Alta"})&" a "&AO2&".",IF(AM2=1,"Tiene apoyo de un familiar con el celular.","")))) | AQ2: 0 | AR2: 0 | AS2: P01 | AT2: =IF(AF2="","","P"&TEXT((MATCH(AF2,{0,5,10,15,20},1)-1)*3+IF(AH2=0,1,MATCH(AN2,{0,5,9},1)),"00")) -> P01 | AU2: =IF(AS2=AT2,"OK","REVISAR") -> OK | AV2: =IF(INDEX(Territorios!$J:$J,MATCH(N2,Territorios!$A:$A,0))=O2,"OK","REVISAR") -> OK | AW2: =IF(INDEX(Territorios!$K:$K,MATCH(N2,Territorios!$A:$A,0))=P2,"OK","REVISAR") -> OK | AX2: =IF(G2>=18,"OK","REVISAR") -> OK | AY2: =IF(COUNT(AH2:AM2)=0,"OK",IF(AJ2>AH2,"REVISAR","OK")) -> OK
A3: sm-496 | B3: BUC-SM496 | C3: 496 | D3: Cristian Páez Pérez | E3: Real · nombre y apellido | F3: Cristian Paez Perez | G3: 28 | H3: Masculino | I3: Masculino | J3: Soltero(A) | K3: 1 | L3: Bucaramanga | M3: 44736 | N3: BUC | O3: Laura Milena Rueda Pinzón | P3: Dra. Adriana Marcela Gómez Duarte | Q3: u-exp-bucaramanga | R3: u-cli-bucaramanga | S3: u-pac-sm-496 | T3: buc-sm496@pacientes.nara.local | U3: 300 000 1496 | V3: Activo | W3: 2 | X3: 2 | Y3: 1 | Z3: 1 | AA3: 1 | AB3: 0 | AC3: 1 | AD3: 0 | AE3: 0 | AF3: =IF(COUNT(W3:AE3)=0,"",SUM(W3:AE3)) -> 8 | AG3: =IF(AF3="","",LOOKUP(AF3,{0,5,10,15,20},{"Mínimo","Leve","Moderado","Moderado-severo","Severo"})) -> Leve | AH3: 1 | AI3: 1 | AJ3: 1 | AK3: 1 | AL3: 0 | AM3: 1 | AN3: =IF(COUNT(AH3:AM3)=0,"",SUM(AH3:AM3)) -> 5 | AO3: =IF(AN3="","",IF(AH3=0,"Baja",LOOKUP(AN3,{0,5,9},{"Baja","Media","Alta"}))) -> Media | AP3: =IF(AN3="","",IF(AH3=0,"Sin teléfono: la capacidad digital queda en Baja.",IF(LOOKUP(AN3-AM3,{0,5,9},{"Baja","Media","Alta"})<>AO3,"El apoyo de un familiar sube el nivel de "&LOOKUP(AN3-AM3,{0,5,9},{"Baja","Media","Alta"})&" a "&AO3&".",IF(AM3=1,"Tiene apoyo de un familiar con el celular.","")))) -> El apoyo de un familiar sube el nivel de Baja a Media. | AQ3: 0 | AR3: 0 | AS3: P05 | AT3: =IF(AF3="","","P"&TEXT((MATCH(AF3,{0,5,10,15,20},1)-1)*3+IF(AH3=0,1,MATCH(AN3,{0,5,9},1)),"00")) -> P05 | AU3: =IF(AS3=AT3,"OK","REVISAR") -> OK | AV3: =IF(INDEX(Territorios!$J:$J,MATCH(N3,Territorios!$A:$A,0))=O3,"OK","REVISAR") -> OK | AW3: =IF(INDEX(Territorios!$K:$K,MATCH(N3,Territorios!$A:$A,0))=P3,"OK","REVISAR") -> OK | AX3: =IF(G3>=18,"OK","REVISAR") -> OK | AY3: =IF(COUNT(AH3:AM3)=0,"OK",IF(AJ3>AH3,"REVISAR","OK")) -> OK
A4: sm-135 | B4: BUC-SM135 | C4: 135 | D4: Silvia Margarita Martínez Franco | E4: Real · nombre y apellido | F4: Silvia Margarita Martinez Franco | G4: 45 | H4: Femenino | I4: Femenino | J4: Casado(A) | K4: 6 | L4: Bucaramanga | M4: 44708 | N4: BUC | O4: Laura Milena Rueda Pinzón | P4: Dra. Adriana Marcela Gómez Duarte | Q4: u-exp-bucaramanga | R4: u-cli-bucaramanga | S4: u-pac-sm-135 | T4: buc-sm135@pacientes.nara.local | U4: 300 000 1135 | V4: Por aprobar | W4: 2 | X4: 1 | Y4: 2 | Z4: 2 | AA4: 2 | AB4: 1 | AC4: 2 | AD4: 1 | AE4: 0 | AF4: =IF(COUNT(W4:AE4)=0,"",SUM(W4:AE4)) -> 13 | AG4: =IF(AF4="","",LOOKUP(AF4,{0,5,10,15,20},{"Mínimo","Leve","Moderado","Moderado-severo","Severo"})) -> Moderado | AH4: 2 | AI4: 2 | AJ4: 2 | AK4: 1 | AL4: 2 | AM4: 0 | AN4: =IF(COUNT(AH4:AM4)=0,"",SUM(AH4:AM4)) -> 9 | AO4: =IF(AN4="","",IF(AH4=0,"Baja",LOOKUP(AN4,{0,5,9},{"Baja","Media","Alta"}))) -> Alta | AP4: =IF(AN4="","",IF(AH4=0,"Sin teléfono: la capacidad digital queda en Baja.",IF(LOOKUP(AN4-AM4,{0,5,9},{"Baja","Media","Alta"})<>AO4,"El apoyo de un familiar sube el nivel de "&LOOKUP(AN4-AM4,{0,5,9},{"Baja","Media","Alta"})&" a "&AO4&".",IF(AM4=1,"Tiene apoyo de un familiar con el celular.","")))) | AQ4: 0 | AR4: 0 | AS4: P09 | AT4: =IF(AF4="","","P"&TEXT((MATCH(AF4,{0,5,10,15,20},1)-1)*3+IF(AH4=0,1,MATCH(AN4,{0,5,9},1)),"00")) -> P09 | AU4: =IF(AS4=AT4,"OK","REVISAR") -> OK | AV4: =IF(INDEX(Territorios!$J:$J,MATCH(N4,Territorios!$A:$A,0))=O4,"OK","REVISAR") -> OK | AW4: =IF(INDEX(Territorios!$K:$K,MATCH(N4,Territorios!$A:$A,0))=P4,"OK","REVISAR") -> OK | AX4: =IF(G4>=18,"OK","REVISAR") -> OK | AY4: =IF(COUNT(AH4:AM4)=0,"OK",IF(AJ4>AH4,"REVISAR","OK")) -> OK
A5: sm-435 | B5: FLO-SM435 | C5: 435 | D5: Sandra Milena García Pinto | E5: Real · nombre y apellido | F5: Sandra Milena Garcia Pinto | G5: 35 | H5: Femenino | I5: Femenino | J5: Soltero(A) | K5: 3 | L5: Floridablanca | M5: 44735 | N5: FLO | O5: Jhon Fredy Ardila Serrano | P5: Dr. Felipe Augusto Quintero Mantilla | Q5: u-exp-floridablanca | R5: u-cli-floridablanca | S5: u-pac-sm-435 | T5: flo-sm435@pacientes.nara.local | U5: 300 000 1435 | V5: Activo | W5: 1 | X5: 1 | Y5: 2 | Z5: 2 | AA5: 1 | AB5: 0 | AC5: 0 | AD5: 0 | AE5: 0 | AF5: =IF(COUNT(W5:AE5)=0,"",SUM(W5:AE5)) -> 7 | AG5: =IF(AF5="","",LOOKUP(AF5,{0,5,10,15,20},{"Mínimo","Leve","Moderado","Moderado-severo","Severo"})) -> Leve | AH5: 1 | AI5: 1 | AJ5: 0 | AK5: 1 | AL5: 0 | AM5: 0 | AN5: =IF(COUNT(AH5:AM5)=0,"",SUM(AH5:AM5)) -> 3 | AO5: =IF(AN5="","",IF(AH5=0,"Baja",LOOKUP(AN5,{0,5,9},{"Baja","Media","Alta"}))) -> Baja | AP5: =IF(AN5="","",IF(AH5=0,"Sin teléfono: la capacidad digital queda en Baja.",IF(LOOKUP(AN5-AM5,{0,5,9},{"Baja","Media","Alta"})<>AO5,"El apoyo de un familiar sube el nivel de "&LOOKUP(AN5-AM5,{0,5,9},{"Baja","Media","Alta"})&" a "&AO5&".",IF(AM5=1,"Tiene apoyo de un familiar con el celular.","")))) | AQ5: 0 | AR5: 0 | AS5: P04 | AT5: =IF(AF5="","","P"&TEXT((MATCH(AF5,{0,5,10,15,20},1)-1)*3+IF(AH5=0,1,MATCH(AN5,{0,5,9},1)),"00")) -> P04 | AU5: =IF(AS5=AT5,"OK","REVISAR") -> OK | AV5: =IF(INDEX(Territorios!$J:$J,MATCH(N5,Territorios!$A:$A,0))=O5,"OK","REVISAR") -> OK | AW5: =IF(INDEX(Territorios!$K:$K,MATCH(N5,Territorios!$A:$A,0))=P5,"OK","REVISAR") -> OK | AX5: =IF(G5>=18,"OK","REVISAR") -> OK | AY5: =IF(COUNT(AH5:AM5)=0,"OK",IF(AJ5>AH5,"REVISAR","OK")) -> OK
A6: sm-434 | B6: FLO-SM434 | C6: 434 | D6: Vanessa Castellanos | E6: Real · nombre y apellido | F6: Vanessa Castellanos | G6: 21 | H6: Femenino | I6: Femenino | J6: Soltero(A) | K6: 2 | L6: Floridablanca | M6: 44735 | N6: FLO | O6: Jhon Fredy Ardila Serrano | P6: Dr. Felipe Augusto Quintero Mantilla | Q6: u-exp-floridablanca | R6: u-cli-floridablanca | S6: u-pac-sm-434 | T6: flo-sm434@pacientes.nara.local | U6: 300 000 1434 | V6: Por aprobar | W6: 2 | X6: 2 | Y6: 1 | Z6: 2 | AA6: 1 | AB6: 1 | AC6: 1 | AD6: 1 | AE6: 0 | AF6: =IF(COUNT(W6:AE6)=0,"",SUM(W6:AE6)) -> 11 | AG6: =IF(AF6="","",LOOKUP(AF6,{0,5,10,15,20},{"Mínimo","Leve","Moderado","Moderado-severo","Severo"})) -> Moderado | AH6: 2 | AI6: 1 | AJ6: 1 | AK6: 2 | AL6: 1 | AM6: 0 | AN6: =IF(COUNT(AH6:AM6)=0,"",SUM(AH6:AM6)) -> 7 | AO6: =IF(AN6="","",IF(AH6=0,"Baja",LOOKUP(AN6,{0,5,9},{"Baja","Media","Alta"}))) -> Media | AP6: =IF(AN6="","",IF(AH6=0,"Sin teléfono: la capacidad digital queda en Baja.",IF(LOOKUP(AN6-AM6,{0,5,9},{"Baja","Media","Alta"})<>AO6,"El apoyo de un familiar sube el nivel de "&LOOKUP(AN6-AM6,{0,5,9},{"Baja","Media","Alta"})&" a "&AO6&".",IF(AM6=1,"Tiene apoyo de un familiar con el celular.","")))) | AQ6: 0 | AR6: 0 | AS6: P08 | AT6: =IF(AF6="","","P"&TEXT((MATCH(AF6,{0,5,10,15,20},1)-1)*3+IF(AH6=0,1,MATCH(AN6,{0,5,9},1)),"00")) -> P08 | AU6: =IF(AS6=AT6,"OK","REVISAR") -> OK | AV6: =IF(INDEX(Territorios!$J:$J,MATCH(N6,Territorios!$A:$A,0))=O6,"OK","REVISAR") -> OK | AW6: =IF(INDEX(Territorios!$K:$K,MATCH(N6,Territorios!$A:$A,0))=P6,"OK","REVISAR") -> OK | AX6: =IF(G6>=18,"OK","REVISAR") -> OK | AY6: =IF(COUNT(AH6:AM6)=0,"OK",IF(AJ6>AH6,"REVISAR","OK")) -> OK
A7: sm-365 | B7: FLO-SM365 | C7: 365 | D7: Paula Pimienta | E7: Real · nombre y apellido | F7: Paula Pimienta | G7: 28 | H7: Femenino | I7: Femenino | J7: Soltero(A) | K7: 4 | L7: Floridablanca | M7: 44729 | N7: FLO | O7: Jhon Fredy Ardila Serrano | P7: Dr. Felipe Augusto Quintero Mantilla | Q7: u-exp-floridablanca | R7: u-cli-floridablanca | S7: u-pac-sm-365 | T7: flo-sm365@pacientes.nara.local | U7: 300 000 1365 | V7: Activo | W7: 2 | X7: 3 | Y7: 3 | Z7: 2 | AA7: 2 | AB7: 2 | AC7: 2 | AD7: 2 | AE7: 0 | AF7: =IF(COUNT(W7:AE7)=0,"",SUM(W7:AE7)) -> 18 | AG7: =IF(AF7="","",LOOKUP(AF7,{0,5,10,15,20},{"Mínimo","Leve","Moderado","Moderado-severo","Severo"})) -> Moderado-severo | AH7: 2 | AI7: 1 | AJ7: 2 | AK7: 2 | AL7: 2 | AM7: 1 | AN7: =IF(COUNT(AH7:AM7)=0,"",SUM(AH7:AM7)) -> 10 | AO7: =IF(AN7="","",IF(AH7=0,"Baja",LOOKUP(AN7,{0,5,9},{"Baja","Media","Alta"}))) -> Alta | AP7: =IF(AN7="","",IF(AH7=0,"Sin teléfono: la capacidad digital queda en Baja.",IF(LOOKUP(AN7-AM7,{0,5,9},{"Baja","Media","Alta"})<>AO7,"El apoyo de un familiar sube el nivel de "&LOOKUP(AN7-AM7,{0,5,9},{"Baja","Media","Alta"})&" a "&AO7&".",IF(AM7=1,"Tiene apoyo de un familiar con el celular.","")))) -> Tiene apoyo de un familiar con el celular. | AQ7: 0 | AR7: 0 | AS7: P12 | AT7: =IF(AF7="","","P"&TEXT((MATCH(AF7,{0,5,10,15,20},1)-1)*3+IF(AH7=0,1,MATCH(AN7,{0,5,9},1)),"00")) -> P12 | AU7: =IF(AS7=AT7,"OK","REVISAR") -> OK | AV7: =IF(INDEX(Territorios!$J:$J,MATCH(N7,Territorios!$A:$A,0))=O7,"OK","REVISAR") -> OK | AW7: =IF(INDEX(Territorios!$K:$K,MATCH(N7,Territorios!$A:$A,0))=P7,"OK","REVISAR") -> OK | AX7: =IF(G7>=18,"OK","REVISAR") -> OK | AY7: =IF(COUNT(AH7:AM7)=0,"OK",IF(AJ7>AH7,"REVISAR","OK")) -> OK
A8: sm-347 | B8: BOG-SM347 | C8: 347 | D8: Ana Rojas | E8: Derivado del usuario | F8: anarojas93@yahoo.es | G8: 57 | H8: Femenino | I8: Femenino | J8: Divorciado(A) | K8: 3 | L8: Bogotá | M8: 44728 | N8: BOG | O8: Natalia Andrea Cárdenas Moreno | P8: Dra. Lucía Marín | Q8: u-exp-bogota | R8: umuvzhvkb | S8: u-pac-sm-347 | T8: bog-sm347@pacientes.nara.local | U8: 300 000 1347 | V8: Activo | W8: 2 | X8: 2 | Y8: 2 | Z8: 2 | AA8: 1 | AB8: 1 | AC8: 1 | AD8: 1 | AE8: 0 | AF8: =IF(COUNT(W8:AE8)=0,"",SUM(W8:AE8)) -> 12 | AG8: =IF(AF8="","",LOOKUP(AF8,{0,5,10,15,20},{"Mínimo","Leve","Moderado","Moderado-severo","Severo"})) -> Moderado | AH8: 1 | AI8: 1 | AJ8: 1 | AK8: 0 | AL8: 1 | AM8: 0 | AN8: =IF(COUNT(AH8:AM8)=0,"",SUM(AH8:AM8)) -> 4 | AO8: =IF(AN8="","",IF(AH8=0,"Baja",LOOKUP(AN8,{0,5,9},{"Baja","Media","Alta"}))) -> Baja | AP8: =IF(AN8="","",IF(AH8=0,"Sin teléfono: la capacidad digital queda en Baja.",IF(LOOKUP(AN8-AM8,{0,5,9},{"Baja","Media","Alta"})<>AO8,"El apoyo de un familiar sube el nivel de "&LOOKUP(AN8-AM8,{0,5,9},{"Baja","Media","Alta"})&" a "&AO8&".",IF(AM8=1,"Tiene apoyo de un familiar con el celular.","")))) | AQ8: 0 | AR8: 0 | AS8: P07 | AT8: =IF(AF8="","","P"&TEXT((MATCH(AF8,{0,5,10,15,20},1)-1)*3+IF(AH8=0,1,MATCH(AN8,{0,5,9},1)),"00")) -> P07 | AU8: =IF(AS8=AT8,"OK","REVISAR") -> OK | AV8: =IF(INDEX(Territorios!$J:$J,MATCH(N8,Territorios!$A:$A,0))=O8,"OK","REVISAR") -> OK | AW8: =IF(INDEX(Territorios!$K:$K,MATCH(N8,Territorios!$A:$A,0))=P8,"OK","REVISAR") -> OK | AX8: =IF(G8>=18,"OK","REVISAR") -> OK | AY8: =IF(COUNT(AH8:AM8)=0,"OK",IF(AJ8>AH8,"REVISAR","OK")) -> OK
A9: sm-321 | B9: BOG-SM321 | C9: 321 | D9: Julieth | E9: Derivado del usuario | F9: juliethz | G9: 31 | H9: Femenino | I9: Femenino | J9: Unión Libre | K9: 2 | L9: Bogota | M9: 44724 | N9: BOG | O9: Natalia Andrea Cárdenas Moreno | P9: Dra. Lucía Marín | Q9: u-exp-bogota | R9: umuvzhvkb | S9: u-pac-sm-321 | T9: bog-sm321@pacientes.nara.local | U9: 300 000 1321 | V9: Rechazado | W9: 3 | X9: 2 | Y9: 1 | Z9: 2 | AA9: 2 | AB9: 2 | AC9: 2 | AD9: 2 | AE9: 0 | AF9: =IF(COUNT(W9:AE9)=0,"",SUM(W9:AE9)) -> 16 | AG9: =IF(AF9="","",LOOKUP(AF9,{0,5,10,15,20},{"Mínimo","Leve","Moderado","Moderado-severo","Severo"})) -> Moderado-severo | AH9: 2 | AI9: 2 | AJ9: 1 | AK9: 1 | AL9: 2 | AM9: 0 | AN9: =IF(COUNT(AH9:AM9)=0,"",SUM(AH9:AM9)) -> 8 | AO9: =IF(AN9="","",IF(AH9=0,"Baja",LOOKUP(AN9,{0,5,9},{"Baja","Media","Alta"}))) -> Media | AP9: =IF(AN9="","",IF(AH9=0,"Sin teléfono: la capacidad digital queda en Baja.",IF(LOOKUP(AN9-AM9,{0,5,9},{"Baja","Media","Alta"})<>AO9,"El apoyo de un familiar sube el nivel de "&LOOKUP(AN9-AM9,{0,5,9},{"Baja","Media","Alta"})&" a "&AO9&".",IF(AM9=1,"Tiene apoyo de un familiar con el celular.","")))) | AQ9: 0 | AR9: 0 | AS9: P11 | AT9: =IF(AF9="","","P"&TEXT((MATCH(AF9,{0,5,10,15,20},1)-1)*3+IF(AH9=0,1,MATCH(AN9,{0,5,9},1)),"00")) -> P11 | AU9: =IF(AS9=AT9,"OK","REVISAR") -> OK | AV9: =IF(INDEX(Territorios!$J:$J,MATCH(N9,Territorios!$A:$A,0))=O9,"OK","REVISAR") -> OK | AW9: =IF(INDEX(Territorios!$K:$K,MATCH(N9,Territorios!$A:$A,0))=P9,"OK","REVISAR") -> OK | AX9: =IF(G9>=18,"OK","REVISAR") -> OK | AY9: =IF(COUNT(AH9:AM9)=0,"OK",IF(AJ9>AH9,"REVISAR","OK")) -> OK
A10: sm-237 | B10: BOG-SM237 | C10: 237 | D10: Isabel | E10: Derivado del usuario | F10: Isabelhdezb | G10: 27 | H10: Femenino | I10: Femenino | J10: Soltero(A) | K10: 5 | L10: Bogotá | M10: 44720 | N10: BOG | O10: Natalia Andrea Cárdenas Moreno | P10: Dra. Lucía Marín | Q10: u-exp-bogota | R10: umuvzhvkb | S10: u-pac-sm-237 | T10: bog-sm237@pacientes.nara.local | U10: 300 000 1237 | V10: Por aprobar | W10: 3 | X10: 3 | Y10: 3 | Z10: 3 | AA10: 2 | AB10: 3 | AC10: 2 | AD10: 2 | AE10: 0 | AF10: =IF(COUNT(W10:AE10)=0,"",SUM(W10:AE10)) -> 21 | AG10: =IF(AF10="","",LOOKUP(AF10,{0,5,10,15,20},{"Mínimo","Leve","Moderado","Moderado-severo","Severo"})) -> Severo | AH10: 2 | AI10: 2 | AJ10: 2 | AK10: 2 | AL10: 2 | AM10: 0 | AN10: =IF(COUNT(AH10:AM10)=0,"",SUM(AH10:AM10)) -> 10 | AO10: =IF(AN10="","",IF(AH10=0,"Baja",LOOKUP(AN10,{0,5,9},{"Baja","Media","Alta"}))) -> Alta | AP10: =IF(AN10="","",IF(AH10=0,"Sin teléfono: la capacidad digital queda en Baja.",IF(LOOKUP(AN10-AM10,{0,5,9},{"Baja","Media","Alta"})<>AO10,"El apoyo de un familiar sube el nivel de "&LOOKUP(AN10-AM10,{0,5,9},{"Baja","Media","Alta"})&" a "&AO10&".",IF(AM10=1,"Tiene apoyo de un familiar con el celular.","")))) | AQ10: 0 | AR10: 0 | AS10: P15 | AT10: =IF(AF10="","","P"&TEXT((MATCH(AF10,{0,5,10,15,20},1)-1)*3+IF(AH10=0,1,MATCH(AN10,{0,5,9},1)),"00")) -> P15 | AU10: =IF(AS10=AT10,"OK","REVISAR") -> OK | AV10: =IF(INDEX(Territorios!$J:$J,MATCH(N10,Territorios!$A:$A,0))=O10,"OK","REVISAR") -> OK | AW10: =IF(INDEX(Territorios!$K:$K,MATCH(N10,Territorios!$A:$A,0))=P10,"OK","REVISAR") -> OK | AX10: =IF(G10>=18,"OK","REVISAR") -> OK | AY10: =IF(COUNT(AH10:AM10)=0,"OK",IF(AJ10>AH10,"REVISAR","OK")) -> OK
A11: sm-352 | B11: CAL-SM352 | C11: 352 | D11: Lorena Lasso | E11: Real · nombre y apellido | F11: Lorena lasso | G11: 32 | H11: Femenino | I11: Femenino | J11: Unión Libre | K11: 1 | L11: Cali | M11: 44728 | N11: CAL | O11: Carlos Andrés Mosquera Valencia | P11: Dra. Paola Andrea Caicedo Arboleda | Q11: u-exp-cali | R11: u-cli-cali | S11: u-pac-sm-352 | T11: cal-sm352@pacientes.nara.local | U11: 300 000 1352 | V11: Aprobado | W11: 2 | X11: 2 | Y11: 3 | Z11: 2 | AA11: 2 | AB11: 2 | AC11: 2 | AD11: 2 | AE11: 0 | AF11: =IF(COUNT(W11:AE11)=0,"",SUM(W11:AE11)) -> 17 | AG11: =IF(AF11="","",LOOKUP(AF11,{0,5,10,15,20},{"Mínimo","Leve","Moderado","Moderado-severo","Severo"})) -> Moderado-severo | AH11: 1 | AI11: 0 | AJ11: 1 | AK11: 1 | AL11: 1 | AM11: 0 | AN11: =IF(COUNT(AH11:AM11)=0,"",SUM(AH11:AM11)) -> 4 | AO11: =IF(AN11="","",IF(AH11=0,"Baja",LOOKUP(AN11,{0,5,9},{"Baja","Media","Alta"}))) -> Baja | AP11: =IF(AN11="","",IF(AH11=0,"Sin teléfono: la capacidad digital queda en Baja.",IF(LOOKUP(AN11-AM11,{0,5,9},{"Baja","Media","Alta"})<>AO11,"El apoyo de un familiar sube el nivel de "&LOOKUP(AN11-AM11,{0,5,9},{"Baja","Media","Alta"})&" a "&AO11&".",IF(AM11=1,"Tiene apoyo de un familiar con el celular.","")))) | AQ11: 0 | AR11: 0 | AS11: P10 | AT11: =IF(AF11="","","P"&TEXT((MATCH(AF11,{0,5,10,15,20},1)-1)*3+IF(AH11=0,1,MATCH(AN11,{0,5,9},1)),"00")) -> P10 | AU11: =IF(AS11=AT11,"OK","REVISAR") -> OK | AV11: =IF(INDEX(Territorios!$J:$J,MATCH(N11,Territorios!$A:$A,0))=O11,"OK","REVISAR") -> OK | AW11: =IF(INDEX(Territorios!$K:$K,MATCH(N11,Territorios!$A:$A,0))=P11,"OK","REVISAR") -> OK | AX11: =IF(G11>=18,"OK","REVISAR") -> OK | AY11: =IF(COUNT(AH11:AM11)=0,"OK",IF(AJ11>AH11,"REVISAR","OK")) -> OK
A12: sm-182 | B12: CAL-SM182 | C12: 182 | D12: Andrés | E12: Real · solo nombre | F12: Andres | G12: 29 | H12: Masculino | I12: Masculino | J12: Soltero(A) | K12: 2 | L12: Cali | M12: 44715 | N12: CAL | O12: Carlos Andrés Mosquera Valencia | P12: Dra. Paola Andrea Caicedo Arboleda | Q12: u-exp-cali | R12: u-cli-cali | S12: u-pac-sm-182 | T12: cal-sm182@pacientes.nara.local | U12: 300 000 1182 | V12: Crisis | W12: 3 | X12: 3 | Y12: 2 | Z12: 3 | AA12: 3 | AB12: 3 | AC12: 3 | AD12: 3 | AE12: 0 | AF12: =IF(COUNT(W12:AE12)=0,"",SUM(W12:AE12)) -> 23 | AG12: =IF(AF12="","",LOOKUP(AF12,{0,5,10,15,20},{"Mínimo","Leve","Moderado","Moderado-severo","Severo"})) -> Severo | AH12: 1 | AI12: 1 | AJ12: 1 | AK12: 1 | AL12: 1 | AM12: 1 | AN12: =IF(COUNT(AH12:AM12)=0,"",SUM(AH12:AM12)) -> 6 | AO12: =IF(AN12="","",IF(AH12=0,"Baja",LOOKUP(AN12,{0,5,9},{"Baja","Media","Alta"}))) -> Media | AP12: =IF(AN12="","",IF(AH12=0,"Sin teléfono: la capacidad digital queda en Baja.",IF(LOOKUP(AN12-AM12,{0,5,9},{"Baja","Media","Alta"})<>AO12,"El apoyo de un familiar sube el nivel de "&LOOKUP(AN12-AM12,{0,5,9},{"Baja","Media","Alta"})&" a "&AO12&".",IF(AM12=1,"Tiene apoyo de un familiar con el celular.","")))) -> Tiene apoyo de un familiar con el celular. | AQ12: 0 | AR12: 0 | AS12: P14 | AT12: =IF(AF12="","","P"&TEXT((MATCH(AF12,{0,5,10,15,20},1)-1)*3+IF(AH12=0,1,MATCH(AN12,{0,5,9},1)),"00")) -> P14 | AU12: =IF(AS12=AT12,"OK","REVISAR") -> OK | AV12: =IF(INDEX(Territorios!$J:$J,MATCH(N12,Territorios!$A:$A,0))=O12,"OK","REVISAR") -> OK | AW12: =IF(INDEX(Territorios!$K:$K,MATCH(N12,Territorios!$A:$A,0))=P12,"OK","REVISAR") -> OK | AX12: =IF(G12>=18,"OK","REVISAR") -> OK | AY12: =IF(COUNT(AH12:AM12)=0,"OK",IF(AJ12>AH12,"REVISAR","OK")) -> OK
A13: sm-204 | B13: CAL-SM204 | C13: 204 | D13: Yessenia Coime | E13: Real · nombre y apellido | F13: Yessenia coime | G13: 19 | H13: Femenino | I13: Femenino | J13: Soltero(A) | K13: 1 | L13: Cali | M13: 44718 | N13: CAL | O13: Carlos Andrés Mosquera Valencia | P13: Dra. Paola Andrea Caicedo Arboleda | Q13: u-exp-cali | R13: u-cli-cali | S13: u-pac-sm-204 | T13: cal-sm204@pacientes.nara.local | U13: 300 000 1204 | V13: Por aprobar | W13: 0 | X13: 0 | Y13: 2 | Z13: 1 | AA13: 0 | AB13: 0 | AC13: 1 | AD13: 0 | AE13: 0 | AF13: =IF(COUNT(W13:AE13)=0,"",SUM(W13:AE13)) -> 4 | AG13: =IF(AF13="","",LOOKUP(AF13,{0,5,10,15,20},{"Mínimo","Leve","Moderado","Moderado-severo","Severo"})) -> Mínimo | AH13: 2 | AI13: 2 | AJ13: 2 | AK13: 2 | AL13: 2 | AM13: 1 | AN13: =IF(COUNT(AH13:AM13)=0,"",SUM(AH13:AM13)) -> 11 | AO13: =IF(AN13="","",IF(AH13=0,"Baja",LOOKUP(AN13,{0,5,9},{"Baja","Media","Alta"}))) -> Alta | AP13: =IF(AN13="","",IF(AH13=0,"Sin teléfono: la capacidad digital queda en Baja.",IF(LOOKUP(AN13-AM13,{0,5,9},{"Baja","Media","Alta"})<>AO13,"El apoyo de un familiar sube el nivel de "&LOOKUP(AN13-AM13,{0,5,9},{"Baja","Media","Alta"})&" a "&AO13&".",IF(AM13=1,"Tiene apoyo de un familiar con el celular.","")))) -> Tiene apoyo de un familiar con el celular. | AQ13: 0 | AR13: 0 | AS13: P03 | AT13: =IF(AF13="","","P"&TEXT((MATCH(AF13,{0,5,10,15,20},1)-1)*3+IF(AH13=0,1,MATCH(AN13,{0,5,9},1)),"00")) -> P03 | AU13: =IF(AS13=AT13,"OK","REVISAR") -> OK | AV13: =IF(INDEX(Territorios!$J:$J,MATCH(N13,Territorios!$A:$A,0))=O13,"OK","REVISAR") -> OK | AW13: =IF(INDEX(Territorios!$K:$K,MATCH(N13,Territorios!$A:$A,0))=P13,"OK","REVISAR") -> OK | AX13: =IF(G13>=18,"OK","REVISAR") -> OK | AY13: =IF(COUNT(AH13:AM13)=0,"OK",IF(AJ13>AH13,"REVISAR","OK")) -> OK
... A16: sm-300 | B16: BAR-SM300 | C16: 300 | D16: Andreina | E16: Real · solo nombre | F16: Andreina | G16: 24 | H16: Femenino | I16: Femenino | J16: Soltero(A) | K16: 1 | L16: Barranquilla | M16: 44723 | N16: BAR | O16: Katherine Paola De la Hoz Charris | P16: Dr. Rafael Enrique Barrios Pertuz | Q16: u-exp-barranquilla | R16: u-cli-barranquilla | S16: u-pac-sm-300 | T16: bar-sm300@pacientes.nara.local | U16: 300 000 1300 | V16: Por aprobar | W16: 1 | X16: 1 | Y16: 1 | Z16: 2 | AA16: 0 | AB16: 0 | AC16: 1 | AD16: 0 | AE16: 0 | AF16: =IF(COUNT(W16:AE16)=0,"",SUM(W16:AE16)) -> 6 | AG16: =IF(AF16="","",LOOKUP(AF16,{0,5,10,15,20},{"Mínimo","Leve","Moderado","Moderado-severo","Severo"})) -> Leve | AH16: 2 | AI16: 2 | AJ16: 2 | AK16: 2 | AL16: 1 | AM16: 0 | AN16: =IF(COUNT(AH16:AM16)=0,"",SUM(AH16:AM16)) -> 9 | AO16: =IF(AN16="","",IF(AH16=0,"Baja",LOOKUP(AN16,{0,5,9},{"Baja","Media","Alta"}))) -> Alta | AP16: =IF(AN16="","",IF(AH16=0,"Sin teléfono: la capacidad digital queda en Baja.",IF(LOOKUP(AN16-AM16,{0,5,9},{"Baja","Media","Alta"})<>AO16,"El apoyo de un familiar sube el nivel de "&LOOKUP(AN16-AM16,{0,5,9},{"Baja","Media","Alta"})&" a "&AO16&".",IF(AM16=1,"Tiene apoyo de un familiar con el celular.","")))) | AQ16: 0 | AR16: 0 | AS16: P06 | AT16: =IF(AF16="","","P"&TEXT((MATCH(AF16,{0,5,10,15,20},1)-1)*3+IF(AH16=0,1,MATCH(AN16,{0,5,9},1)),"00")) -> P06 | AU16: =IF(AS16=AT16,"OK","REVISAR") -> OK | AV16: =IF(INDEX(Territorios!$J:$J,MATCH(N16,Territorios!$A:$A,0))=O16,"OK","REVISAR") -> OK | AW16: =IF(INDEX(Territorios!$K:$K,MATCH(N16,Territorios!$A:$A,0))=P16,"OK","REVISAR") -> OK | AX16: =IF(G16>=18,"OK","REVISAR") -> OK | AY16: =IF(COUNT(AH16:AM16)=0,"OK",IF(AJ16>AH16,"REVISAR","OK")) -> OK
A17: sm-327 | B17: BUC-SM327 | C17: 327 | D17: Beatriz Elena Ramírez Coronado | E17: Real · nombre y apellido | F17: BEATRIZ ELENA RAMIREZ CORONADO | G17: 32 | H17: Femenino | I17: Femenino | J17: Soltero(A) | K17: 2 | L17: Bucaramanga | M17: 44725 | N17: BUC | O17: Laura Milena Rueda Pinzón | P17: Dra. Adriana Marcela Gómez Duarte | Q17: u-exp-bucaramanga | R17: u-cli-bucaramanga | S17: u-pac-sm-327 | T17: buc-sm327@pacientes.nara.local | U17: 300 000 1327 | V17: Sin evaluación | AF17: =IF(COUNT(W17:AE17)=0,"",SUM(W17:AE17)) | AG17: =IF(AF17="","",LOOKUP(AF17,{0,5,10,15,20},{"Mínimo","Leve","Moderado","Moderado-severo","Severo"})) | AN17: =IF(COUNT(AH17:AM17)=0,"",SUM(AH17:AM17)) | AO17: =IF(AN17="","",IF(AH17=0,"Baja",LOOKUP(AN17,{0,5,9},{"Baja","Media","Alta"}))) | AP17: =IF(AN17="","",IF(AH17=0,"Sin teléfono: la capacidad digital queda en Baja.",IF(LOOKUP(AN17-AM17,{0,5,9},{"Baja","Media","Alta"})<>AO17,"El apoyo de un familiar sube el nivel de "&LOOKUP(AN17-AM17,{0,5,9},{"Baja","Media","Alta"})&" a "&AO17&".",IF(AM17=1,"Tiene apoyo de un familiar con el celular.","")))) | AT17: =IF(AF17="","","P"&TEXT((MATCH(AF17,{0,5,10,15,20},1)-1)*3+IF(AH17=0,1,MATCH(AN17,{0,5,9},1)),"00")) | AU17: =IF(AS17=AT17,"OK","REVISAR") -> OK | AV17: =IF(INDEX(Territorios!$J:$J,MATCH(N17,Territorios!$A:$A,0))=O17,"OK","REVISAR") -> OK | AW17: =IF(INDEX(Territorios!$K:$K,MATCH(N17,Territorios!$A:$A,0))=P17,"OK","REVISAR") -> OK | AX17: =IF(G17>=18,"OK","REVISAR") -> OK | AY17: =IF(COUNT(AH17:AM17)=0,"OK",IF(AJ17>AH17,"REVISAR","OK")) -> OK
A18: sm-433 | B18: FLO-SM433 | C18: 433 | D18: Tatiana | E18: Real · solo nombre | F18: Tatiana | G18: 32 | H18: Femenino | I18: Femenino | J18: Casado(A) | K18: 3 | L18: Floridablanca | M18: 44735 | N18: FLO | O18: Jhon Fredy Ardila Serrano | P18: Dr. Felipe Augusto Quintero Mantilla | Q18: u-exp-floridablanca | R18: u-cli-floridablanca | S18: u-pac-sm-433 | T18: flo-sm433@pacientes.nara.local | U18: 300 000 1433 | V18: Sin evaluación | AF18: =IF(COUNT(W18:AE18)=0,"",SUM(W18:AE18)) | AG18: =IF(AF18="","",LOOKUP(AF18,{0,5,10,15,20},{"Mínimo","Leve","Moderado","Moderado-severo","Severo"})) | AN18: =IF(COUNT(AH18:AM18)=0,"",SUM(AH18:AM18)) | AO18: =IF(AN18="","",IF(AH18=0,"Baja",LOOKUP(AN18,{0,5,9},{"Baja","Media","Alta"}))) | AP18: =IF(AN18="","",IF(AH18=0,"Sin teléfono: la capacidad digital queda en Baja.",IF(LOOKUP(AN18-AM18,{0,5,9},{"Baja","Media","Alta"})<>AO18,"El apoyo de un familiar sube el nivel de "&LOOKUP(AN18-AM18,{0,5,9},{"Baja","Media","Alta"})&" a "&AO18&".",IF(AM18=1,"Tiene apoyo de un familiar con el celular.","")))) | AT18: =IF(AF18="","","P"&TEXT((MATCH(AF18,{0,5,10,15,20},1)-1)*3+IF(AH18=0,1,MATCH(AN18,{0,5,9},1)),"00")) | AU18: =IF(AS18=AT18,"OK","REVISAR") -> OK | AV18: =IF(INDEX(Territorios!$J:$J,MATCH(N18,Territorios!$A:$A,0))=O18,"OK","REVISAR") -> OK | AW18: =IF(INDEX(Territorios!$K:$K,MATCH(N18,Territorios!$A:$A,0))=P18,"OK","REVISAR") -> OK | AX18: =IF(G18>=18,"OK","REVISAR") -> OK | AY18: =IF(COUNT(AH18:AM18)=0,"OK",IF(AJ18>AH18,"REVISAR","OK")) -> OK
A19: sm-207 | B19: BOG-SM207 | C19: 207 | D19: Juli | E19: Derivado del usuario | F19: Juli16BTS | G19: 18 | H19: Femenino | I19: Femenino | J19: Soltero(A) | K19: 4 | L19: Bogota | M19: 44718 | N19: BOG | O19: Natalia Andrea Cárdenas Moreno | P19: Dra. Lucía Marín | Q19: u-exp-bogota | R19: umuvzhvkb | S19: u-pac-sm-207 | T19: bog-sm207@pacientes.nara.local | U19: 300 000 1207 | V19: Sin evaluación | AF19: =IF(COUNT(W19:AE19)=0,"",SUM(W19:AE19)) | AG19: =IF(AF19="","",LOOKUP(AF19,{0,5,10,15,20},{"Mínimo","Leve","Moderado","Moderado-severo","Severo"})) | AN19: =IF(COUNT(AH19:AM19)=0,"",SUM(AH19:AM19)) | AO19: =IF(AN19="","",IF(AH19=0,"Baja",LOOKUP(AN19,{0,5,9},{"Baja","Media","Alta"}))) | AP19: =IF(AN19="","",IF(AH19=0,"Sin teléfono: la capacidad digital queda en Baja.",IF(LOOKUP(AN19-AM19,{0,5,9},{"Baja","Media","Alta"})<>AO19,"El apoyo de un familiar sube el nivel de "&LOOKUP(AN19-AM19,{0,5,9},{"Baja","Media","Alta"})&" a "&AO19&".",IF(AM19=1,"Tiene apoyo de un familiar con el celular.","")))) | AT19: =IF(AF19="","","P"&TEXT((MATCH(AF19,{0,5,10,15,20},1)-1)*3+IF(AH19=0,1,MATCH(AN19,{0,5,9},1)),"00")) | AU19: =IF(AS19=AT19,"OK","REVISAR") -> OK | AV19: =IF(INDEX(Territorios!$J:$J,MATCH(N19,Territorios!$A:$A,0))=O19,"OK","REVISAR") -> OK | AW19: =IF(INDEX(Territorios!$K:$K,MATCH(N19,Territorios!$A:$A,0))=P19,"OK","REVISAR") -> OK | AX19: =IF(G19>=18,"OK","REVISAR") -> OK | AY19: =IF(COUNT(AH19:AM19)=0,"OK",IF(AJ19>AH19,"REVISAR","OK")) -> OK
A20: sm-406 | B20: CAL-SM406 | C20: 406 | D20: Stiven | E20: Real · solo nombre | F20: Stiven | G20: 18 | H20: Masculino | I20: Masculino | J20: Soltero(A) | K20: 2 | L20: Cali | M20: 44734 | N20: CAL | O20: Carlos Andrés Mosquera Valencia | P20: Dra. Paola Andrea Caicedo Arboleda | Q20: u-exp-cali | R20: u-cli-cali | S20: u-pac-sm-406 | T20: cal-sm406@pacientes.nara.local | U20: 300 000 1406 | V20: Sin evaluación | AF20: =IF(COUNT(W20:AE20)=0,"",SUM(W20:AE20)) | AG20: =IF(AF20="","",LOOKUP(AF20,{0,5,10,15,20},{"Mínimo","Leve","Moderado","Moderado-severo","Severo"})) | AN20: =IF(COUNT(AH20:AM20)=0,"",SUM(AH20:AM20)) | AO20: =IF(AN20="","",IF(AH20=0,"Baja",LOOKUP(AN20,{0,5,9},{"Baja","Media","Alta"}))) | AP20: =IF(AN20="","",IF(AH20=0,"Sin teléfono: la capacidad digital queda en Baja.",IF(LOOKUP(AN20-AM20,{0,5,9},{"Baja","Media","Alta"})<>AO20,"El apoyo de un familiar sube el nivel de "&LOOKUP(AN20-AM20,{0,5,9},{"Baja","Media","Alta"})&" a "&AO20&".",IF(AM20=1,"Tiene apoyo de un familiar con el celular.","")))) | AT20: =IF(AF20="","","P"&TEXT((MATCH(AF20,{0,5,10,15,20},1)-1)*3+IF(AH20=0,1,MATCH(AN20,{0,5,9},1)),"00")) | AU20: =IF(AS20=AT20,"OK","REVISAR") -> OK | AV20: =IF(INDEX(Territorios!$J:$J,MATCH(N20,Territorios!$A:$A,0))=O20,"OK","REVISAR") -> OK | AW20: =IF(INDEX(Territorios!$K:$K,MATCH(N20,Territorios!$A:$A,0))=P20,"OK","REVISAR") -> OK | AX20: =IF(G20>=18,"OK","REVISAR") -> OK | AY20: =IF(COUNT(AH20:AM20)=0,"OK",IF(AJ20>AH20,"REVISAR","OK")) -> OK
A21: sm-187 | B21: BAR-SM187 | C21: 187 | D21: Esmy | E21: Derivado del usuario | F21: Esmy.nam | G21: 28 | H21: Femenino | I21: Femenino | J21: Unión Libre | K21: 2 | L21: Barranquilla | M21: 44715 | N21: BAR | O21: Katherine Paola De la Hoz Charris | P21: Dr. Rafael Enrique Barrios Pertuz | Q21: u-exp-barranquilla | R21: u-cli-barranquilla | S21: u-pac-sm-187 | T21: bar-sm187@pacientes.nara.local | U21: 300 000 1187 | V21: Sin evaluación | AF21: =IF(COUNT(W21:AE21)=0,"",SUM(W21:AE21)) | AG21: =IF(AF21="","",LOOKUP(AF21,{0,5,10,15,20},{"Mínimo","Leve","Moderado","Moderado-severo","Severo"})) | AN21: =IF(COUNT(AH21:AM21)=0,"",SUM(AH21:AM21)) | AO21: =IF(AN21="","",IF(AH21=0,"Baja",LOOKUP(AN21,{0,5,9},{"Baja","Media","Alta"}))) | AP21: =IF(AN21="","",IF(AH21=0,"Sin teléfono: la capacidad digital queda en Baja.",IF(LOOKUP(AN21-AM21,{0,5,9},{"Baja","Media","Alta"})<>AO21,"El apoyo de un familiar sube el nivel de "&LOOKUP(AN21-AM21,{0,5,9},{"Baja","Media","Alta"})&" a "&AO21&".",IF(AM21=1,"Tiene apoyo de un familiar con el celular.","")))) | AT21: =IF(AF21="","","P"&TEXT((MATCH(AF21,{0,5,10,15,20},1)-1)*3+IF(AH21=0,1,MATCH(AN21,{0,5,9},1)),"00")) | AU21: =IF(AS21=AT21,"OK","REVISAR") -> OK | AV21: =IF(INDEX(Territorios!$J:$J,MATCH(N21,Territorios!$A:$A,0))=O21,"OK","REVISAR") -> OK | AW21: =IF(INDEX(Territorios!$K:$K,MATCH(N21,Territorios!$A:$A,0))=P21,"OK","REVISAR") -> OK | AX21: =IF(G21>=18,"OK","REVISAR") -> OK | AY21: =IF(COUNT(AH21:AM21)=0,"OK",IF(AJ21>AH21,"REVISAR","OK")) -> OK

Sheet Flujo
A1: ID paciente | B1: Nombre | C1: Territorio | D1: Perfil | E1: Estado | F1: Visita programada | G1: Fecha de evaluación | H1: Duración entrevista (min) | I1: Decisión clínica | J1: Fecha de la decisión | K1: Clínico que decidió | L1: Motivo del rechazo | M1: Alerta de crisis | N1: Origen de la alerta | O1: Fecha y hora de la alerta | P1: Alerta dirigida a | Q1: Consentimiento obligatorio (3/3) | R1: Autoriza contacto por teléfono o WhatsApp | S1: Autoriza manilla | T1: Autoriza remisión | U1: Ruta (servicio y frecuencia) | V1: Nº servicios | W1: Meses | X1: Curso propuesto | Y1: Semanas del curso | Z1: Motivo del curso | AA1: Modalidad del curso | AB1: Canal del curso | AC1: Último contacto | AD1: Canal del último contacto | AE1: Días sin contacto | AF1: Alerta «Sin contacto» (14 días o más) | AG1: Adherencia % | AH1: Cuenta lista para la app (perfilListo) | AI1: Próximo paso | AJ1: Check · pregunta 9 > 0 ⇒ Crisis | AK1: Check · manilla autorizada | AL1: Check · estado y decisión | AM1: Check · días sin contacto (14 y 28) | AN1: Check · canal según capacidad
A2: sm-436 | B2: =INDEX(Pacientes!$D:$D,MATCH(A2,Pacientes!$A:$A,0)) -> Darly Yasmin Solano | C2: =INDEX(Pacientes!$N:$N,MATCH(A2,Pacientes!$A:$A,0)) -> BUC | D2: =INDEX(Pacientes!$AS:$AS,MATCH(A2,Pacientes!$A:$A,0))&"" -> P01 | E2: Inactivo | G2: 46254 | H2: 34 | I2: Aprobado | J2: 46255 | K2: Dra. Adriana Marcela Gómez Duarte | Q2: Sí | R2: Sí | S2: No aplica | T2: No | U2: Llamada de seguimiento (Mensual) · Técnicas guiadas (Material impreso) · Revisita del experto (Mensual) · Grupo de apoyo en la vereda (Mensual) · Cursos y cuentos (Curso con el experto) | V2: 5 | W2: 3 | X2: Calma cuando tiembla | Y2: 4 | Z2: para manejar el miedo y el estrés | AA2: Curso con el experto | AB2: Cuadernillo impreso · audio en la visita | AC2: 46268 | AD2: Llamada de seguimiento | AE2: =IF(AC2="","",DATE(2026,10,8)-AC2) -> 35 | AF2: =IF(AE2="","",IF(AE2>=14,"Sí","No")) -> Sí | AG2: 18 | AH2: Sí | AI2: Más de 4 semanas sin contacto: el experto la busca en la próxima revisita. | AJ2: =IF(AND(N(INDEX(Pacientes!$AE:$AE,MATCH(A2,Pacientes!$A:$A,0)))>0,E2<>"Crisis"),"REVISAR","OK") -> OK | AK2: =IF(AND(ISNUMBER(SEARCH("Manilla",U2)),S2<>"Sí",LEFT(U2,8)<>"Sin ruta"),"REVISAR","OK") -> OK | AL2: =IF(OR(AND(E2="Sin evaluación",I2<>""),AND(E2="Por aprobar",I2<>"Pendiente"),AND(OR(E2="Aprobado",E2="Activo",E2="Inactivo"),I2<>"Aprobado"),AND(E2="Rechazado",I2<>"Rechazado")),"REVISAR","OK") -> OK | AM2: =IF(E2="Inactivo",IF(N(AE2)>28,"OK","REVISAR"),IF(E2="Activo",IF(N(AE2)<=28,"OK","REVISAR"),"OK")) -> OK | AN2: =IF(AD2="","OK",IF(OR(AND(INDEX(Pacientes!$AO:$AO,MATCH(A2,Pacientes!$A:$A,0))="Alta",ISNUMBER(SEARCH("app",AD2))),AND(INDEX(Pacientes!$AO:$AO,MATCH(A2,Pacientes!$A:$A,0))="Media",ISNUMBER(SEARCH("WhatsApp",AD2))),AND(INDEX(Pacientes!$AO:$AO,MATCH(A2,Pacientes!$A:$A,0))="Baja",OR(ISNUMBER(SEARCH("Llamada",AD2)),ISNUMBER(SEARCH("Revisita",AD2))))),"OK","REVISAR")) -> OK
A3: sm-496 | B3: =INDEX(Pacientes!$D:$D,MATCH(A3,Pacientes!$A:$A,0)) -> Cristian Páez Pérez | C3: =INDEX(Pacientes!$N:$N,MATCH(A3,Pacientes!$A:$A,0)) -> BUC | D3: =INDEX(Pacientes!$AS:$AS,MATCH(A3,Pacientes!$A:$A,0))&"" -> P05 | E3: Activo | G3: 46273 | H3: 41 | I3: Aprobado | J3: 46274 | K3: Dra. Adriana Marcela Gómez Duarte | Q3: Sí | R3: Sí | S3: No aplica | T3: No | U3: Check-ins por WhatsApp (1 vez por semana) · Videos psicoeducativos (Serie completa) · Técnicas guiadas (En audio) · Revisita del experto (Mensual) · Grupo de apoyo en la vereda (Mensual) · Cursos y cuentos (Curso guiado por TEO) | V3: 6 | W3: 3 | X3: Ánimo, paso a paso | Y3: 4 | Z3: porque tiene el ánimo bajo | AA3: Curso guiado por TEO | AB3: WhatsApp · portada, audio y pregunta | AC3: 46302 | AD3: Check-in por WhatsApp | AE3: =IF(AC3="","",DATE(2026,10,8)-AC3) -> 1 | AF3: =IF(AE3="","",IF(AE3>=14,"Sí","No")) -> No | AG3: 82 | AH3: Sí | AI3: Seguir la ruta; próxima revisión cada 4 semanas. | AJ3: =IF(AND(N(INDEX(Pacientes!$AE:$AE,MATCH(A3,Pacientes!$A:$A,0)))>0,E3<>"Crisis"),"REVISAR","OK") -> OK | AK3: =IF(AND(ISNUMBER(SEARCH("Manilla",U3)),S3<>"Sí",LEFT(U3,8)<>"Sin ruta"),"REVISAR","OK") -> OK | AL3: =IF(OR(AND(E3="Sin evaluación",I3<>""),AND(E3="Por aprobar",I3<>"Pendiente"),AND(OR(E3="Aprobado",E3="Activo",E3="Inactivo"),I3<>"Aprobado"),AND(E3="Rechazado",I3<>"Rechazado")),"REVISAR","OK") -> OK | AM3: =IF(E3="Inactivo",IF(N(AE3)>28,"OK","REVISAR"),IF(E3="Activo",IF(N(AE3)<=28,"OK","REVISAR"),"OK")) -> OK | AN3: =IF(AD3="","OK",IF(OR(AND(INDEX(Pacientes!$AO:$AO,MATCH(A3,Pacientes!$A:$A,0))="Alta",ISNUMBER(SEARCH("app",AD3))),AND(INDEX(Pacientes!$AO:$AO,MATCH(A3,Pacientes!$A:$A,0))="Media",ISNUMBER(SEARCH("WhatsApp",AD3))),AND(INDEX(Pacientes!$AO:$AO,MATCH(A3,Pacientes!$A:$A,0))="Baja",OR(ISNUMBER(SEARCH("Llamada",AD3)),ISNUMBER(SEARCH("Revisita",AD3))))),"OK","REVISAR")) -> OK
A4: sm-135 | B4: =INDEX(Pacientes!$D:$D,MATCH(A4,Pacientes!$A:$A,0)) -> Silvia Margarita Martínez Franco | C4: =INDEX(Pacientes!$N:$N,MATCH(A4,Pacientes!$A:$A,0)) -> BUC | D4: =INDEX(Pacientes!$AS:$AS,MATCH(A4,Pacientes!$A:$A,0))&"" -> P09 | E4: Por aprobar | G4: 46302 | H4: 38 | I4: Pendiente | Q4: Sí | R4: Sí | S4: Sí | T4: No | U4: Estado de ánimo (Diario) · Psicólogo clínico (Mensual) · Acompañante con IA (TEO) (Entre sesiones) · Check-ins por WhatsApp (3 veces por semana) · Manilla de monitoreo (6 meses) · Videos psicoeducativos (Serie completa) · Técnicas guiadas (En audio) · Problem Management Plus (PM+) (5 sesiones semanales) · Cursos y cuentos (Curso con el experto) | V4: 9 | W4: 6 | X4: Dormir mejor después del sismo | Y4: 4 | Z4: porque duerme mal desde el sismo | AA4: Curso con el experto | AB4: App · leer y escuchar | AE4: =IF(AC4="","",DATE(2026,10,8)-AC4) | AF4: =IF(AE4="","",IF(AE4>=14,"Sí","No")) | AH4: No | AI4: El clínico del territorio aprueba o rechaza el perfil y la ruta. | AJ4: =IF(AND(N(INDEX(Pacientes!$AE:$AE,MATCH(A4,Pacientes!$A:$A,0)))>0,E4<>"Crisis"),"REVISAR","OK") -> OK | AK4: =IF(AND(ISNUMBER(SEARCH("Manilla",U4)),S4<>"Sí",LEFT(U4,8)<>"Sin ruta"),"REVISAR","OK") -> OK | AL4: =IF(OR(AND(E4="Sin evaluación",I4<>""),AND(E4="Por aprobar",I4<>"Pendiente"),AND(OR(E4="Aprobado",E4="Activo",E4="Inactivo"),I4<>"Aprobado"),AND(E4="Rechazado",I4<>"Rechazado")),"REVISAR","OK") -> OK | AM4: =IF(E4="Inactivo",IF(N(AE4)>28,"OK","REVISAR"),IF(E4="Activo",IF(N(AE4)<=28,"OK","REVISAR"),"OK")) -> OK | AN4: =IF(AD4="","OK",IF(OR(AND(INDEX(Pacientes!$AO:$AO,MATCH(A4,Pacientes!$A:$A,0))="Alta",ISNUMBER(SEARCH("app",AD4))),AND(INDEX(Pacientes!$AO:$AO,MATCH(A4,Pacientes!$A:$A,0))="Media",ISNUMBER(SEARCH("WhatsApp",AD4))),AND(INDEX(Pacientes!$AO:$AO,MATCH(A4,Pacientes!$A:$A,0))="Baja",OR(ISNUMBER(SEARCH("Llamada",AD4)),ISNUMBER(SEARCH("Revisita",AD4))))),"OK","REVISAR")) -> OK
A5: sm-435 | B5: =INDEX(Pacientes!$D:$D,MATCH(A5,Pacientes!$A:$A,0)) -> Sandra Milena García Pinto | C5: =INDEX(Pacientes!$N:$N,MATCH(A5,Pacientes!$A:$A,0)) -> FLO | D5: =INDEX(Pacientes!$AS:$AS,MATCH(A5,Pacientes!$A:$A,0))&"" -> P04 | E5: Activo | G5: 46275 | H5: 45 | I5: Aprobado | J5: 46276 | K5: Dr. Felipe Augusto Quintero Mantilla | Q5: Sí | R5: Sí | S5: No aplica | T5: No | U5: Llamada de seguimiento (Mensual) · Técnicas guiadas (Material impreso) · Revisita del experto (Cada 2 semanas) · Grupo de apoyo en la vereda (Mensual) · Cursos y cuentos (Curso con el experto) | V5: 5 | W5: 3 | X5: Dormir mejor después del sismo | Y5: 4 | Z5: porque duerme mal desde el sismo | AA5: Curso con el experto | AB5: Cuadernillo impreso · audio en la visita | AC5: 46301 | AD5: Revisita del experto | AE5: =IF(AC5="","",DATE(2026,10,8)-AC5) -> 2 | AF5: =IF(AE5="","",IF(AE5>=14,"Sí","No")) -> No | AG5: 75 | AH5: Sí | AI5: Seguir la ruta; próxima revisión cada 4 semanas. | AJ5: =IF(AND(N(INDEX(Pacientes!$AE:$AE,MATCH(A5,Pacientes!$A:$A,0)))>0,E5<>"Crisis"),"REVISAR","OK") -> OK | AK5: =IF(AND(ISNUMBER(SEARCH("Manilla",U5)),S5<>"Sí",LEFT(U5,8)<>"Sin ruta"),"REVISAR","OK") -> OK | AL5: =IF(OR(AND(E5="Sin evaluación",I5<>""),AND(E5="Por aprobar",I5<>"Pendiente"),AND(OR(E5="Aprobado",E5="Activo",E5="Inactivo"),I5<>"Aprobado"),AND(E5="Rechazado",I5<>"Rechazado")),"REVISAR","OK") -> OK | AM5: =IF(E5="Inactivo",IF(N(AE5)>28,"OK","REVISAR"),IF(E5="Activo",IF(N(AE5)<=28,"OK","REVISAR"),"OK")) -> OK | AN5: =IF(AD5="","OK",IF(OR(AND(INDEX(Pacientes!$AO:$AO,MATCH(A5,Pacientes!$A:$A,0))="Alta",ISNUMBER(SEARCH("app",AD5))),AND(INDEX(Pacientes!$AO:$AO,MATCH(A5,Pacientes!$A:$A,0))="Media",ISNUMBER(SEARCH("WhatsApp",AD5))),AND(INDEX(Pacientes!$AO:$AO,MATCH(A5,Pacientes!$A:$A,0))="Baja",OR(ISNUMBER(SEARCH("Llamada",AD5)),ISNUMBER(SEARCH("Revisita",AD5))))),"OK","REVISAR")) -> OK
